Workbook

Sheet Export Table
A1: KEY | E1: Section Name | F1: Setup Location | G1: Setup Sub-Location | H1: Sub-Setup Assembly | I1: IO type | J1: Zone | K1: Device Type | L1: Device Tag | M1: Device Location | N1: Circuit | O1: Power Source | P1: Status | R1: Cell Count
A2: Abbrev. | B2: Name | C2: Rows | E2: AC Body | F2: =EXP_AC[[#This Row],[Setup Location]] -> HPS | G2: =EXP_AC[[#This Row],[Setup Sub-Location]] -> AC-A | H2: =EXP_AC[[#This Row],[Sub-Setup Assembly]] -> Vessel | I2: =EXP_AC[[#This Row],[IO type]] -> 0 | J2: =EXP_AC[[#This Row],[Zone]] -> AC Body | K2: =EXP_AC[[#This Row],[Device Type]] -> Old 1" | L2: =EXP_AC[[#This Row],[Device Tag]] -> A | M2: =EXP_AC[[#This Row],[Device Location]] -> 0 | N2: =EXP_AC[[#This Row],[Circuit]] -> 0 | O2: =EXP_AC[[#This Row],[Power Source]] -> 0 | P2: =EXP_AC[[#This Row],[Status]] -> Active | R2: 1
A3: AC | B3: Autoclave Body | C3: 100 | E3: AC Body | F3: =EXP_AC[[#This Row],[Setup Location]] -> HPS | G3: =EXP_AC[[#This Row],[Setup Sub-Location]] -> AC-AA | H3: =EXP_AC[[#This Row],[Sub-Setup Assembly]] -> Vessel | I3: =EXP_AC[[#This Row],[IO type]] -> 0 | J3: =EXP_AC[[#This Row],[Zone]] -> AC Body | K3: =EXP_AC[[#This Row],[Device Type]] -> New 1" - Bar Seal | L3: =EXP_AC[[#This Row],[Device Tag]] -> AA | M3: =EXP_AC[[#This Row],[Device Location]] -> 0 | N3: =EXP_AC[[#This Row],[Circuit]] -> 0 | O3: =EXP_AC[[#This Row],[Power Source]] -> 0 | P3: =EXP_AC[[#This Row],[Status]] -> Design | R3: =R2+1 -> 2
A4: AD | B4: Adaptors | C4: 110 | E4: AC Body | F4: =EXP_AC[[#This Row],[Setup Location]] -> HPS | G4: =EXP_AC[[#This Row],[Setup Sub-Location]] -> AC-AB | H4: =EXP_AC[[#This Row],[Sub-Setup Assembly]] -> Vessel | I4: =EXP_AC[[#This Row],[IO type]] -> 0 | J4: =EXP_AC[[#This Row],[Zone]] -> AC Body | K4: =EXP_AC[[#This Row],[Device Type]] -> New 1" - Keyed | L4: =EXP_AC[[#This Row],[Device Tag]] -> AB | M4: =EXP_AC[[#This Row],[Device Location]] -> 0 | N4: =EXP_AC[[#This Row],[Circuit]] -> 0 | O4: =EXP_AC[[#This Row],[Power Source]] -> 0 | P4: =EXP_AC[[#This Row],[Status]] -> Design | R4: =R3+1 -> 3
A5: CR | B5: Crosses | C5: 60 | E5: AC Body | F5: =EXP_AC[[#This Row],[Setup Location]] -> HPS | G5: =EXP_AC[[#This Row],[Setup Sub-Location]] -> AC-AC | H5: =EXP_AC[[#This Row],[Sub-Setup Assembly]] -> Vessel | I5: =EXP_AC[[#This Row],[IO type]] -> 0 | J5: =EXP_AC[[#This Row],[Zone]] -> AC Body | K5: =EXP_AC[[#This Row],[Device Type]] -> TZM-13-260-10 | L5: =EXP_AC[[#This Row],[Device Tag]] -> AC | M5: =EXP_AC[[#This Row],[Device Location]] -> 0 | N5: =EXP_AC[[#This Row],[Circuit]] -> 0 | O5: =EXP_AC[[#This Row],[Power Source]] -> 0 | P5: =EXP_AC[[#This Row],[Status]] -> New | R5: =R4+1 -> 4
A6: CUP | B6: Couplings | C6: 50 | E6: AC Body | F6: =EXP_AC[[#This Row],[Setup Location]] -> HPS | G6: =EXP_AC[[#This Row],[Setup Sub-Location]] -> AC-AD | H6: =EXP_AC[[#This Row],[Sub-Setup Assembly]] -> Vessel | I6: =EXP_AC[[#This Row],[IO type]] -> 0 | J6: =EXP_AC[[#This Row],[Zone]] -> AC Body | K6: =EXP_AC[[#This Row],[Device Type]] -> 76OD-20ID-TZM | L6: =EXP_AC[[#This Row],[Device Tag]] -> AD | M6: =EXP_AC[[#This Row],[Device Location]] -> 0 | N6: =EXP_AC[[#This Row],[Circuit]] -> 0 | O6: =EXP_AC[[#This Row],[Power Source]] -> 0 | P6: =EXP_AC[[#This Row],[Status]] -> Design | R6: =R5+1 -> 5
A7: EL | B7: Elbows | C7: 50 | E7: AC Body | F7: =EXP_AC[[#This Row],[Setup Location]] -> HPS | G7: =EXP_AC[[#This Row],[Setup Sub-Location]] -> AC-AE | H7: =EXP_AC[[#This Row],[Sub-Setup Assembly]] -> Vessel | I7: =EXP_AC[[#This Row],[IO type]] -> 0 | J7: =EXP_AC[[#This Row],[Zone]] -> AC Body | K7: =EXP_AC[[#This Row],[Device Type]] -> 76OD-20ID-TZM-Thread | L7: =EXP_AC[[#This Row],[Device Tag]] -> AE | M7: =EXP_AC[[#This Row],[Device Location]] -> 0 | N7: =EXP_AC[[#This Row],[Circuit]] -> 0 | O7: =EXP_AC[[#This Row],[Power Source]] -> 0 | P7: =EXP_AC[[#This Row],[Status]] -> Design | R7: =R6+1 -> 6
A8: FI | B8: Filters | C8: 50 | E8: AC Body | F8: =EXP_AC[[#This Row],[Setup Location]] -> HPS | G8: =EXP_AC[[#This Row],[Setup Sub-Location]] -> AC-AF | H8: =EXP_AC[[#This Row],[Sub-Setup Assembly]] -> Vessel | I8: =EXP_AC[[#This Row],[IO type]] -> 0 | J8: =EXP_AC[[#This Row],[Zone]] -> AC Body | K8: =EXP_AC[[#This Row],[Device Type]] -> 76OD-50ID-TZM-Thread-Hemi | L8: =EXP_AC[[#This Row],[Device Tag]] -> AF | M8: =EXP_AC[[#This Row],[Device Location]] -> 0 | N8: =EXP_AC[[#This Row],[Circuit]] -> 0 | O8: =EXP_AC[[#This Row],[Power Source]] -> 0 | P8: =EXP_AC[[#This Row],[Status]] -> Design | R8: =R7+1 -> 7
A9: FUR | B9: Furniture | C9: 400 | E9: AC Body | F9: =EXP_AC[[#This Row],[Setup Location]] -> HPS | G9: =EXP_AC[[#This Row],[Setup Sub-Location]] -> AC-AG | H9: =EXP_AC[[#This Row],[Sub-Setup Assembly]] -> Vessel | I9: =EXP_AC[[#This Row],[IO type]] -> 0 | J9: =EXP_AC[[#This Row],[Zone]] -> AC Body | K9: =EXP_AC[[#This Row],[Device Type]] -> 90OD-70ID-TZM | L9: =EXP_AC[[#This Row],[Device Tag]] -> AG | M9: =EXP_AC[[#This Row],[Device Location]] -> 0 | N9: =EXP_AC[[#This Row],[Circuit]] -> 0 | O9: =EXP_AC[[#This Row],[Power Source]] -> 0 | P9: =EXP_AC[[#This Row],[Status]] -> Design | R9: =R8+1 -> 8
A10: GKT | B10: Gaskets | C10: 100 | E10: AC Body | F10: =EXP_AC[[#This Row],[Setup Location]] -> HPS | G10: =EXP_AC[[#This Row],[Setup Sub-Location]] -> AC-B | H10: =EXP_AC[[#This Row],[Sub-Setup Assembly]] -> Vessel | I10: =EXP_AC[[#This Row],[IO type]] -> 0 | J10: =EXP_AC[[#This Row],[Zone]] -> AC Body | K10: =EXP_AC[[#This Row],[Device Type]] -> Short 1" - Rene 41 | L10: =EXP_AC[[#This Row],[Device Tag]] -> B | M10: =EXP_AC[[#This Row],[Device Location]] -> 0 | N10: =EXP_AC[[#This Row],[Circuit]] -> 0 | O10: =EXP_AC[[#This Row],[Power Source]] -> 0 | P10: =EXP_AC[[#This Row],[Status]] -> Active | R10: =R9+1 -> 9
A11: GN | B11: Grand Nuts | C11: 100 | E11: AC Body | F11: =EXP_AC[[#This Row],[Setup Location]] -> HPS | G11: =EXP_AC[[#This Row],[Setup Sub-Location]] -> AC-C | H11: =EXP_AC[[#This Row],[Sub-Setup Assembly]] -> Vessel | I11: =EXP_AC[[#This Row],[IO type]] -> 0 | J11: =EXP_AC[[#This Row],[Zone]] -> AC Body | K11: =EXP_AC[[#This Row],[Device Type]] -> Short 1" - Rene 41 | L11: =EXP_AC[[#This Row],[Device Tag]] -> C | M11: =EXP_AC[[#This Row],[Device Location]] -> 0 | N11: =EXP_AC[[#This Row],[Circuit]] -> 0 | O11: =EXP_AC[[#This Row],[Power Source]] -> 0 | P11: =EXP_AC[[#This Row],[Status]] -> Active | R11: =R10+1 -> 10
A12: HDA | B12: Head Assemblies | C12: 0 | E12: AC Body | F12: =EXP_AC[[#This Row],[Setup Location]] -> HPS | G12: =EXP_AC[[#This Row],[Setup Sub-Location]] -> AC-D | H12: =EXP_AC[[#This Row],[Sub-Setup Assembly]] -> Vessel | I12: =EXP_AC[[#This Row],[IO type]] -> 0 | J12: =EXP_AC[[#This Row],[Zone]] -> AC Body | K12: =EXP_AC[[#This Row],[Device Type]] -> Short 1" - Rene 41 | L12: =EXP_AC[[#This Row],[Device Tag]] -> D | M12: =EXP_AC[[#This Row],[Device Location]] -> 0 | N12: =EXP_AC[[#This Row],[Circuit]] -> 0 | O12: =EXP_AC[[#This Row],[Power Source]] -> 0 | P12: =EXP_AC[[#This Row],[Status]] -> Active | R12: =R11+1 -> 11
A13: NUT | B13: Nuts | C13: 100 | E13: AC Body | F13: =EXP_AC[[#This Row],[Setup Location]] -> HPS | G13: =EXP_AC[[#This Row],[Setup Sub-Location]] -> AC-DUM-1 | H13: =EXP_AC[[#This Row],[Sub-Setup Assembly]] -> Vessel | I13: =EXP_AC[[#This Row],[IO type]] -> 0 | J13: =EXP_AC[[#This Row],[Zone]] -> AC Body | K13: =EXP_AC[[#This Row],[Device Type]] -> SS Dummy | L13: =EXP_AC[[#This Row],[Device Tag]] -> DUM-1 | M13: =EXP_AC[[#This Row],[Device Location]] -> 0 | N13: =EXP_AC[[#This Row],[Circuit]] -> 0 | O13: =EXP_AC[[#This Row],[Power Source]] -> 0 | P13: =EXP_AC[[#This Row],[Status]] -> Active | R13: =R12+1 -> 12
A14: NV | B14: Needle Valves | C14: 150 | E14: AC Body | F14: =EXP_AC[[#This Row],[Setup Location]] -> HPS | G14: =EXP_AC[[#This Row],[Setup Sub-Location]] -> AC-E | H14: =EXP_AC[[#This Row],[Sub-Setup Assembly]] -> Vessel | I14: =EXP_AC[[#This Row],[IO type]] -> 0 | J14: =EXP_AC[[#This Row],[Zone]] -> AC Body | K14: =EXP_AC[[#This Row],[Device Type]] -> Short 1" - Inconel | L14: =EXP_AC[[#This Row],[Device Tag]] -> E | M14: =EXP_AC[[#This Row],[Device Location]] -> 0 | N14: =EXP_AC[[#This Row],[Circuit]] -> 0 | O14: =EXP_AC[[#This Row],[Power Source]] -> 0 | P14: =EXP_AC[[#This Row],[Status]] -> Active | R14: =R13+1 -> 13
... A21: TW | B21: Thrust Washer | C21: 50 | E21: AC Body | F21: =EXP_AC[[#This Row],[Setup Location]] -> HPS | G21: =EXP_AC[[#This Row],[Setup Sub-Location]] -> AC-N | H21: =EXP_AC[[#This Row],[Sub-Setup Assembly]] -> Vessel | I21: =EXP_AC[[#This Row],[IO type]] -> 0 | J21: =EXP_AC[[#This Row],[Zone]] -> AC Body | K21: =EXP_AC[[#This Row],[Device Type]] -> New 1" | L21: =EXP_AC[[#This Row],[Device Tag]] -> N | M21: =EXP_AC[[#This Row],[Device Location]] -> 0 | N21: =EXP_AC[[#This Row],[Circuit]] -> 0 | O21: =EXP_AC[[#This Row],[Power Source]] -> 0 | P21: =EXP_AC[[#This Row],[Status]] -> UCSB | R21: =R20+1 -> 20
E22: AC Body | F22: =EXP_AC[[#This Row],[Setup Location]] -> HPS | G22: =EXP_AC[[#This Row],[Setup Sub-Location]] -> AC-P | H22: =EXP_AC[[#This Row],[Sub-Setup Assembly]] -> Vessel | I22: =EXP_AC[[#This Row],[IO type]] -> 0 | J22: =EXP_AC[[#This Row],[Zone]] -> AC Body | K22: =EXP_AC[[#This Row],[Device Type]] -> New 1" | L22: =EXP_AC[[#This Row],[Device Tag]] -> P | M22: =EXP_AC[[#This Row],[Device Location]] -> 0 | N22: =EXP_AC[[#This Row],[Circuit]] -> 0 | O22: =EXP_AC[[#This Row],[Power Source]] -> 0 | P22: =EXP_AC[[#This Row],[Status]] -> Active | R22: =R21+1 -> 21
E23: AC Body | F23: =EXP_AC[[#This Row],[Setup Location]] -> HPS | G23: =EXP_AC[[#This Row],[Setup Sub-Location]] -> AC-Parr | H23: =EXP_AC[[#This Row],[Sub-Setup Assembly]] -> Vessel | I23: =EXP_AC[[#This Row],[IO type]] -> 0 | J23: =EXP_AC[[#This Row],[Zone]] -> AC Body | K23: =EXP_AC[[#This Row],[Device Type]] -> Parr 4" | L23: =EXP_AC[[#This Row],[Device Tag]] -> Parr | M23: =EXP_AC[[#This Row],[Device Location]] -> 0 | N23: =EXP_AC[[#This Row],[Circuit]] -> 0 | O23: =EXP_AC[[#This Row],[Power Source]] -> 0 | P23: =EXP_AC[[#This Row],[Status]] -> Active | R23: =R22+1 -> 22
E24: AC Body | F24: =EXP_AC[[#This Row],[Setup Location]] -> HPS | G24: =EXP_AC[[#This Row],[Setup Sub-Location]] -> AC-Q | H24: =EXP_AC[[#This Row],[Sub-Setup Assembly]] -> Vessel | I24: =EXP_AC[[#This Row],[IO type]] -> 0 | J24: =EXP_AC[[#This Row],[Zone]] -> AC Body | K24: =EXP_AC[[#This Row],[Device Type]] -> New 1" | L24: =EXP_AC[[#This Row],[Device Tag]] -> Q | M24: =EXP_AC[[#This Row],[Device Location]] -> 0 | N24: =EXP_AC[[#This Row],[Circuit]] -> 0 | O24: =EXP_AC[[#This Row],[Power Source]] -> 0 | P24: =EXP_AC[[#This Row],[Status]] -> Active | R24: =R23+1 -> 23
E25: AC Body | F25: =EXP_AC[[#This Row],[Setup Location]] -> HPS | G25: =EXP_AC[[#This Row],[Setup Sub-Location]] -> AC-R | H25: =EXP_AC[[#This Row],[Sub-Setup Assembly]] -> Vessel | I25: =EXP_AC[[#This Row],[IO type]] -> 0 | J25: =EXP_AC[[#This Row],[Zone]] -> AC Body | K25: =EXP_AC[[#This Row],[Device Type]] -> New 1" | L25: =EXP_AC[[#This Row],[Device Tag]] -> R | M25: =EXP_AC[[#This Row],[Device Location]] -> 0 | N25: =EXP_AC[[#This Row],[Circuit]] -> 0 | O25: =EXP_AC[[#This Row],[Power Source]] -> 0 | P25: =EXP_AC[[#This Row],[Status]] -> Active | R25: =R24+1 -> 24
E26: AC Body | F26: =EXP_AC[[#This Row],[Setup Location]] -> HPS | G26: =EXP_AC[[#This Row],[Setup Sub-Location]] -> AC-TA | H26: =EXP_AC[[#This Row],[Sub-Setup Assembly]] -> Vessel | I26: =EXP_AC[[#This Row],[IO type]] -> 0 | J26: =EXP_AC[[#This Row],[Zone]] -> AC Body | K26: =EXP_AC[[#This Row],[Device Type]] -> TZM-13-260-10 | L26: =EXP_AC[[#This Row],[Device Tag]] -> TA | M26: =EXP_AC[[#This Row],[Device Location]] -> 0 | N26: =EXP_AC[[#This Row],[Circuit]] -> 0 | O26: =EXP_AC[[#This Row],[Power Source]] -> 0 | P26: =EXP_AC[[#This Row],[Status]] -> Active | R26: =R25+1 -> 25
E27: AC Body | F27: =EXP_AC[[#This Row],[Setup Location]] -> HPS | G27: =EXP_AC[[#This Row],[Setup Sub-Location]] -> AC-TB | H27: =EXP_AC[[#This Row],[Sub-Setup Assembly]] -> Vessel | I27: =EXP_AC[[#This Row],[IO type]] -> 0 | J27: =EXP_AC[[#This Row],[Zone]] -> AC Body | K27: =EXP_AC[[#This Row],[Device Type]] -> TZM-13-260-10 | L27: =EXP_AC[[#This Row],[Device Tag]] -> TB | M27: =EXP_AC[[#This Row],[Device Location]] -> 0 | N27: =EXP_AC[[#This Row],[Circuit]] -> 0 | O27: =EXP_AC[[#This Row],[Power Source]] -> 0 | P27: =EXP_AC[[#This Row],[Status]] -> Active | R27: =R26+1 -> 26
E28: AC Body | F28: =EXP_AC[[#This Row],[Setup Location]] -> HPS | G28: =EXP_AC[[#This Row],[Setup Sub-Location]] -> AC-TC | H28: =EXP_AC[[#This Row],[Sub-Setup Assembly]] -> Vessel | I28: =EXP_AC[[#This Row],[IO type]] -> 0 | J28: =EXP_AC[[#This Row],[Zone]] -> AC Body | K28: =EXP_AC[[#This Row],[Device Type]] -> TZM-13-260-10 | L28: =EXP_AC[[#This Row],[Device Tag]] -> TC | M28: =EXP_AC[[#This Row],[Device Location]] -> 0 | N28: =EXP_AC[[#This Row],[Circuit]] -> 0 | O28: =EXP_AC[[#This Row],[Power Source]] -> 0 | P28: =EXP_AC[[#This Row],[Status]] -> Active | R28: =R27+1 -> 27
E29: AC Body | F29: =EXP_AC[[#This Row],[Setup Location]] -> HPS | G29: =EXP_AC[[#This Row],[Setup Sub-Location]] -> AC-TD | H29: =EXP_AC[[#This Row],[Sub-Setup Assembly]] -> Vessel | I29: =EXP_AC[[#This Row],[IO type]] -> 0 | J29: =EXP_AC[[#This Row],[Zone]] -> AC Body | K29: =EXP_AC[[#This Row],[Device Type]] -> TZM-13-260-10 | L29: =EXP_AC[[#This Row],[Device Tag]] -> TD | M29: =EXP_AC[[#This Row],[Device Location]] -> 0 | N29: =EXP_AC[[#This Row],[Circuit]] -> 0 | O29: =EXP_AC[[#This Row],[Power Source]] -> 0 | P29: =EXP_AC[[#This Row],[Status]] -> Active | R29: =R28+1 -> 28
E30: AC Body | F30: =EXP_AC[[#This Row],[Setup Location]] -> HPS | G30: =EXP_AC[[#This Row],[Setup Sub-Location]] -> AC-TE | H30: =EXP_AC[[#This Row],[Sub-Setup Assembly]] -> Vessel | I30: =EXP_AC[[#This Row],[IO type]] -> 0 | J30: =EXP_AC[[#This Row],[Zone]] -> AC Body | K30: =EXP_AC[[#This Row],[Device Type]] -> TZM-13-260-10 | L30: =EXP_AC[[#This Row],[Device Tag]] -> TE | M30: =EXP_AC[[#This Row],[Device Location]] -> 0 | N30: =EXP_AC[[#This Row],[Circuit]] -> 0 | O30: =EXP_AC[[#This Row],[Power Source]] -> 0 | P30: =EXP_AC[[#This Row],[Status]] -> Active | R30: =R29+1 -> 29
E31: AC Body | F31: =EXP_AC[[#This Row],[Setup Location]] -> HPS | G31: =EXP_AC[[#This Row],[Setup Sub-Location]] -> AC-TF | H31: =EXP_AC[[#This Row],[Sub-Setup Assembly]] -> Vessel | I31: =EXP_AC[[#This Row],[IO type]] -> 0 | J31: =EXP_AC[[#This Row],[Zone]] -> AC Body | K31: =EXP_AC[[#This Row],[Device Type]] -> TZM-13-260-13 | L31: =EXP_AC[[#This Row],[Device Tag]] -> TF | M31: =EXP_AC[[#This Row],[Device Location]] -> 0 | N31: =EXP_AC[[#This Row],[Circuit]] -> 0 | O31: =EXP_AC[[#This Row],[Power Source]] -> 0 | P31: =EXP_AC[[#This Row],[Status]] -> New | R31: =R30+1 -> 30
E32: AC Body | F32: =EXP_AC[[#This Row],[Setup Location]] -> HPS | G32: =EXP_AC[[#This Row],[Setup Sub-Location]] -> AC-TG | H32: =EXP_AC[[#This Row],[Sub-Setup Assembly]] -> Vessel | I32: =EXP_AC[[#This Row],[IO type]] -> 0 | J32: =EXP_AC[[#This Row],[Zone]] -> AC Body | K32: =EXP_AC[[#This Row],[Device Type]] -> TZM-13-260-10-DE | L32: =EXP_AC[[#This Row],[Device Tag]] -> TG | M32: =EXP_AC[[#This Row],[Device Location]] -> 0 | N32: =EXP_AC[[#This Row],[Circuit]] -> 0 | O32: =EXP_AC[[#This Row],[Power Source]] -> 0 | P32: =EXP_AC[[#This Row],[Status]] -> New | R32: =R31+1 -> 31
E33: AC Body | F33: =EXP_AC[[#This Row],[Setup Location]] -> HPS | G33: =EXP_AC[[#This Row],[Setup Sub-Location]] -> AC-Z | H33: =EXP_AC[[#This Row],[Sub-Setup Assembly]] -> Vessel | I33: =EXP_AC[[#This Row],[IO type]] -> 0 | J33: =EXP_AC[[#This Row],[Zone]] -> AC Body | K33: =EXP_AC[[#This Row],[Device Type]] -> 2" | L33: =EXP_AC[[#This Row],[Device Tag]] -> Z | M33: =EXP_AC[[#This Row],[Device Location]] -> 0 | N33: =EXP_AC[[#This Row],[Circuit]] -> 0 | O33: =EXP_AC[[#This Row],[Power Source]] -> 0 | P33: =EXP_AC[[#This Row],[Status]] -> UCSB | R33: =R32+1 -> 32
... E101: AC Body | F101: =EXP_AC[[#This Row],[Setup Location]] -> HPS | G101: =EXP_AC[[#This Row],[Setup Sub-Location]] -> 0 | H101: =EXP_AC[[#This Row],[Sub-Setup Assembly]] -> Vessel | I101: =EXP_AC[[#This Row],[IO type]] -> 0 | J101: =EXP_AC[[#This Row],[Zone]] -> 0 | K101: =EXP_AC[[#This Row],[Device Type]] -> 0 | L101: =EXP_AC[[#This Row],[Device Tag]] -> #VALUE! | M101: =EXP_AC[[#This Row],[Device Location]] -> 0 | N101: =EXP_AC[[#This Row],[Circuit]] -> 0 | O101: =EXP_AC[[#This Row],[Power Source]] -> 0 | P101: =EXP_AC[[#This Row],[Status]] | R101: =R100+1 -> 100
E102: Adaptor | F102: =AD!CA2 -> HPS | G102: =AD!CB2 -> AC | H102: =AD!CC2 -> Vessel | I102: =AD!CD2 -> 0 | J102: =AD!CE2 -> Adaptors | K102: =AD!CF2 -> 60-21HF4HF6 | L102: =AD!CG2 -> AD-K2 | M102: =AD!CH2 -> 0 | ... P102: =AD!CK2 -> Superceded | R102: =R101+1 -> 101
E103: Adaptor | F103: =AD!CA3 -> HPS | G103: =AD!CB3 -> AC | H103: =AD!CC3 -> Vessel | I103: =AD!CD3 -> 0 | J103: =AD!CE3 -> Adaptors | K103: =AD!CF3 -> 60-21HF4HF6 | L103: =AD!CG3 -> AD-L1 | M103: =AD!CH3 -> 0 | ... P103: =AD!CK3 -> Superceded | R103: =R102+1 -> 102
E104: Adaptor | F104: =AD!CA4 -> HPS | G104: =AD!CB4 -> AC | H104: =AD!CC4 -> Vessel | I104: =AD!CD4 -> 0 | J104: =AD!CE4 -> Adaptors | K104: =AD!CF4 -> 60-21HF4HF6 | L104: =AD!CG4 -> AD-N1 | M104: =AD!CH4 -> 0 | ... P104: =AD!CK4 -> Superceded | R104: =R103+1 -> 103
E105: Adaptor | F105: =AD!CA5 -> HPS | G105: =AD!CB5 -> AC | H105: =AD!CC5 -> Vessel | I105: =AD!CD5 -> 0 | J105: =AD!CE5 -> Adaptors | K105: =AD!CF5 -> 60-21HF4HF6 | L105: =AD!CG5 -> AD-P1 | M105: =AD!CH5 -> 0 | ... P105: =AD!CK5 -> Superceded | R105: =R104+1 -> 104
E106: Adaptor | F106: =AD!CA6 -> HPS | G106: =AD!CB6 -> AC | H106: =AD!CC6 -> Vessel | I106: =AD!CD6 -> 0 | J106: =AD!CE6 -> Adaptors | K106: =AD!CF6 -> 60-21HF4HF6 | L106: =AD!CG6 -> AD-Q1 | M106: =AD!CH6 -> 0 | ... P106: =AD!CK6 -> Superceded | R106: =R105+1 -> 105
E107: Adaptor | F107: =AD!CA7 -> HPS | G107: =AD!CB7 -> AC | H107: =AD!CC7 -> Vessel | I107: =AD!CD7 -> 0 | J107: =AD!CE7 -> Adaptors | K107: =AD!CF7 -> 60-21HF4HF6 | L107: =AD!CG7 -> AD-R1 | M107: =AD!CH7 -> 0 | ... P107: =AD!CK7 -> Superceded | R107: =R106+1 -> 106
E108: Adaptor | F108: =AD!CA8 -> HPS | G108: =AD!CB8 -> AC | H108: =AD!CC8 -> Vessel | I108: =AD!CD8 -> 0 | J108: =AD!CE8 -> Adaptors | K108: =AD!CF8 -> 60-21HF6HM4 | L108: =AD!CG8 -> AD-1 | M108: =AD!CH8 -> 0 | ... P108: =AD!CK8 -> Active | R108: =R107+1 -> 107
E109: Adaptor | F109: =AD!CA9 -> HPS | G109: =AD!CB9 -> AC | H109: =AD!CC9 -> Vessel | I109: =AD!CD9 -> 0 | J109: =AD!CE9 -> Adaptors | K109: =AD!CF9 -> 60-21HF6HM4 | L109: =AD!CG9 -> AD-2 | M109: =AD!CH9 -> 0 | ... P109: =AD!CK9 -> Active | R109: =R108+1 -> 108
E110: Adaptor | F110: =AD!CA10 -> HPS | G110: =AD!CB10 -> AC | H110: =AD!CC10 -> Vessel | I110: =AD!CD10 -> 0 | J110: =AD!CE10 -> Adaptors | K110: =AD!CF10 -> 60-21HF6HM4 | L110: =AD!CG10 -> AD-3 | M110: =AD!CH10 -> 0 | ... P110: =AD!CK10 -> Active | R110: =R109+1 -> 109
E111: Adaptor | F111: =AD!CA11 -> HPS | G111: =AD!CB11 -> AC | H111: =AD!CC11 -> Vessel | I111: =AD!CD11 -> 0 | J111: =AD!CE11 -> Adaptors | K111: =AD!CF11 -> 60-21HF6HM4 | L111: =AD!CG11 -> AD-4 | M111: =AD!CH11 -> 0 | ... P111: =AD!CK11 -> Active | R111: =R110+1 -> 110
E112: Adaptor | F112: =AD!CA12 -> HPS | G112: =AD!CB12 -> AC | H112: =AD!CC12 -> Vessel | I112: =AD!CD12 -> 0 | J112: =AD!CE12 -> Adaptors | K112: =AD!CF12 -> 60-21HF6HM4 | L112: =AD!CG12 -> AD-5 | M112: =AD!CH12 -> 0 | ... P112: =AD!CK12 -> Active | R112: =R111+1 -> 111
E113: Adaptor | F113: =AD!CA13 -> HPS | G113: =AD!CB13 -> AC | H113: =AD!CC13 -> Vessel | I113: =AD!CD13 -> 0 | J113: =AD!CE13 -> Adaptors | K113: =AD!CF13 -> 60-21HF6HM4 | L113: =AD!CG13 -> AD-6 | M113: =AD!CH13 -> 0 | ... P113: =AD!CK13 -> Active | R113: =R112+1 -> 112
...

Sheet DWG Naming
A1: Drawing Naming Convention
A2: MATS-HPS-AC-AD-2a_Rev1
A4: MATS | B4: HPS | C4: AC | D4: AD | E4: 2a | G4: 1
A5: Lab name | B5: Hi Press Sys | C5: Autoclave | D5: Letter designation of the body | E5: Sub-part | G5: Revision
D6: See Bodies Sheet | G6: 0 | H6: Pre-release
D7: Sub-parts that go to a given body should share the two-letter prefix | E7: No Number | F7: Body | G7: 1 | H7: First Released Version
E8: 1 | F8: Couplings | G8: 2 | H8: Second Released Version
E9: 2 | F9: Nuts
E10: 3 | F10: Gaskets
E11: 4 | F11: Grand Nuts
E12: 5 | F12: Thrust Washers
E13: 6 | F13: Set Screws
E14: 7 | F14: Nozzles
E15: 8 | F15: Safety Heads
E16: 9 | F16: Brace Plates
E17: 9a | F17: Brace Plate 1 for AD
E18: 9b | F18: Brace Plate 2 for AD
E19: 10 | F19: Auxiliary Parts
A21: AC | B21: Autoclave Bodies
A22: AD | B22: Adaptors
A23: CR | B23: Crosses
A24: CUP | B24: Couplings
A25: EL | B25: Elbows
A26: FI | B26: Filters
A27: FUR | B27: Furniture
A28: GKT | B28: Gaskets
A29: GN | B29: Grand Nuts
A30: HDA | B30: Head Assemblies
A31: NUT | B31: Nuts
A32: NV | B32: Needle Valves
... A39: TW | B39: Thrust Washer

Sheet AC
A1: Status | B1: UID | C1: Part Type | D1: Name | E1: Location | F1: Pressure Design (MPa) | G1: Pressure Design (psi) | H1: Temperature Design (C) | I1: Reactor Body Material | J1: Heat Treatment | K1: Corrosion | L1: Diameter Inner (inch) | M1: Diameter Inner (mm) | N1: Length Inner (inch) | O1: Length Inner (mm) | P1: Volume Inner (ml) | Q1: Weight Body (g) | R1: Body Thread | S1: Pressure Interlock (MPa) | T1: Pressure Burst Nominal (psi) | U1: Pressure Burst Nominal (MPa) | V1: Profile | W1: Manufacture | X1: Date Manufactured | Y1: Lot # | Z1: PO | AA1: Link to Schematic Drawing | CA1: EXP Style | CB1: Setup Location | CC1: Setup Sub-Location | CD1: Sub-Setup Assembly | CE1: IO type | CF1: Zone | CG1: Device Type | CH1: Device Tag | CI1: Device Location | CJ1: Circuit | CK1: Power Source | CL1: Status
A2: Active | B2: AC-A | C2: AC Body | D2: Old 1" | E2: Lehigh | F2: 250 | G2: 36259 | H2: 575 | I2: Rene 41 | J2: Precipitation Hardened | K2: None Observed | L2: 1 | M2: 25.4 | N2: 10 | O2: 254 | P2: 129.8 | Q2: 3248.97 | R2: ACME 2"-5 | S2: 265 | T2: 50000 | U2: 345 | W2: UCSB | X2: 39173 | Y2: - | Z2: - | AA2: https://drive.google.com/open?id=1E_SEOWW8QEa0jqxBg-RQJgkI8SOz6Fw7&authuser=jrd419%40lehigh.edu&usp=drive_fs | CA2: Table Format | CB2: HPS | CC2: =AC[[#This Row],[UID]] -> AC-A | CD2: Vessel | CF2: =AC[[#This Row],[Part Type]] -> AC Body | CG2: =AC[[#This Row],[Name]] -> Old 1" | CH2: =RIGHT(AC[[#This Row],[UID]],LEN(AC[[#This Row],[UID]])-3) -> A | CL2: =IF(AC[[#This Row],[Status]]=0,"",AC[[#This Row],[Status]]) -> Active
A3: Design | B3: AC-AA | C3: AC Body | D3: New 1" - Bar Seal | E3: Lehigh | F3: - | G3: - | H3: - | I3: TZM | J3: Stress-relieved | K3: - | L3: - | M3: - | N3: - | O3: - | P3: - | Q3: - | R3: - | S3: - | T3: - | U3: - | W3: - | X3: - | Y3: - | Z3: - | AA3: - | CB3: HPS | CC3: =AC[[#This Row],[UID]] -> AC-AA | CD3: Vessel | CF3: =AC[[#This Row],[Part Type]] -> AC Body | CG3: =AC[[#This Row],[Name]] -> New 1" - Bar Seal | CH3: =RIGHT(AC[[#This Row],[UID]],LEN(AC[[#This Row],[UID]])-3) -> AA | CL3: =IF(AC[[#This Row],[Status]]=0,"",AC[[#This Row],[Status]]) -> Design
A4: Design | B4: AC-AB | C4: AC Body | D4: New 1" - Keyed | E4: Lehigh | F4: - | G4: - | H4: - | I4: TZM | J4: Stress-relieved | K4: - | L4: - | M4: - | N4: - | O4: - | P4: - | Q4: - | R4: - | S4: - | T4: - | U4: - | W4: - | X4: - | Y4: - | Z4: - | AA4: - | CB4: HPS | CC4: =AC[[#This Row],[UID]] -> AC-AB | CD4: Vessel | CF4: =AC[[#This Row],[Part Type]] -> AC Body | CG4: =AC[[#This Row],[Name]] -> New 1" - Keyed | CH4: =RIGHT(AC[[#This Row],[UID]],LEN(AC[[#This Row],[UID]])-3) -> AB | CL4: =IF(AC[[#This Row],[Status]]=0,"",AC[[#This Row],[Status]]) -> Design
A5: New | B5: AC-AC | C5: AC Body | D5: TZM-13-260-10 | E5: Lehigh | F5: 160 | G5: 22400 | H5: 600 | I5: TZM | J5: Stress-relieved | K5: - | L5: =13/25.4 -> 0.51181102 | M5: 13 | N5: - | O5: - | P5: - | Q5: - | R5: - | S5: - | T5: - | U5: - | W5: - | X5: - | Y5: - | Z5: - | AA5: - | CB5: HPS | CC5: =AC[[#This Row],[UID]] -> AC-AC | CD5: Vessel | CF5: =AC[[#This Row],[Part Type]] -> AC Body | CG5: =AC[[#This Row],[Name]] -> TZM-13-260-10 | CH5: =RIGHT(AC[[#This Row],[UID]],LEN(AC[[#This Row],[UID]])-3) -> AC | CL5: =IF(AC[[#This Row],[Status]]=0,"",AC[[#This Row],[Status]]) -> New
A6: Design | B6: AC-AD | C6: AC Body | D6: 76OD-20ID-TZM | E6: Lehigh | F6: 10-175 | G6: 22400 | H6: 550 | I6: TZM | J6: Stress-relieved | K6: - | L6: =20/25.4 -> 0.78740157 | M6: 20 | N6: - | O6: - | P6: - | Q6: - | R6: - | S6: - | T6: - | U6: - | W6: - | X6: - | Y6: - | Z6: - | AA6: - | CB6: HPS | CC6: =AC[[#This Row],[UID]] -> AC-AD | CD6: Vessel | CF6: =AC[[#This Row],[Part Type]] -> AC Body | CG6: =AC[[#This Row],[Name]] -> 76OD-20ID-TZM | CH6: =RIGHT(AC[[#This Row],[UID]],LEN(AC[[#This Row],[UID]])-3) -> AD | CL6: =IF(AC[[#This Row],[Status]]=0,"",AC[[#This Row],[Status]]) -> Design
A7: Design | B7: AC-AE | C7: AC Body | D7: 76OD-20ID-TZM-Thread | E7: Lehigh | F7: 10-175 | G7: =1750*14 -> 24500 | H7: 1050 | I7: TZM B387-19, Type 364 | J7: Stress-relieved | K7: None Observed | CB7: HPS | CC7: =AC[[#This Row],[UID]] -> AC-AE | CD7: Vessel | CF7: =AC[[#This Row],[Part Type]] -> AC Body | CG7: =AC[[#This Row],[Name]] -> 76OD-20ID-TZM-Thread | CH7: =RIGHT(AC[[#This Row],[UID]],LEN(AC[[#This Row],[UID]])-3) -> AE | CL7: =IF(AC[[#This Row],[Status]]=0,"",AC[[#This Row],[Status]]) -> Design
A8: Design | B8: AC-AF | C8: AC Body | D8: 76OD-50ID-TZM-Thread-Hemi | E8: Lehigh | F8: 10 | G8: =100*14 -> 1400 | H8: 1050 | I8: TZM B387-19, Type 364 | J8: Stress-relieved | K8: None Observed | CB8: HPS | CC8: =AC[[#This Row],[UID]] -> AC-AF | CD8: Vessel | CF8: =AC[[#This Row],[Part Type]] -> AC Body | CG8: =AC[[#This Row],[Name]] -> 76OD-50ID-TZM-Thread-Hemi | CH8: =RIGHT(AC[[#This Row],[UID]],LEN(AC[[#This Row],[UID]])-3) -> AF | CL8: =IF(AC[[#This Row],[Status]]=0,"",AC[[#This Row],[Status]]) -> Design
A9: Design | B9: AC-AG | C9: AC Body | D9: 90OD-70ID-TZM | E9: Lehigh | F9: 10 | G9: 1400 | H9: 1050 | I9: TZM B387-19, Type 364 | J9: Stress-relieved | K9: None Observed | CB9: HPS | CC9: =AC[[#This Row],[UID]] -> AC-AG | CD9: Vessel | CF9: =AC[[#This Row],[Part Type]] -> AC Body | CG9: =AC[[#This Row],[Name]] -> 90OD-70ID-TZM | CH9: =RIGHT(AC[[#This Row],[UID]],LEN(AC[[#This Row],[UID]])-3) -> AG | CL9: =IF(AC[[#This Row],[Status]]=0,"",AC[[#This Row],[Status]]) -> Design
A10: Active | B10: AC-B | C10: AC Body | D10: Short 1" - Rene 41 | E10: Lehigh | F10: 250 | G10: 36259 | H10: 575 | I10: Rene 41 | J10: Precipitation Hardened | K10: Heavily Corroded | L10: 1 | M10: 25.4 | N10: 5 | O10: 127 | P10: 64.7 | Q10: 1713.78 | R10: ACME 2"-5 | S10: 265 | T10: 50000 | U10: 345 | W10: UCSB | X10: 39814 | Y10: - | Z10: - | AA10: https://drive.google.com/open?id=1ufwTYDKRXg9fWiytCJ2PaqUQyXha5s67&authuser=jrd419%40lehigh.edu&usp=drive_fs | CB10: HPS | CC10: =AC[[#This Row],[UID]] -> AC-B | CD10: Vessel | CF10: =AC[[#This Row],[Part Type]] -> AC Body | CG10: =AC[[#This Row],[Name]] -> Short 1" - Rene 41 | CH10: =RIGHT(AC[[#This Row],[UID]],LEN(AC[[#This Row],[UID]])-3) -> B | CL10: =IF(AC[[#This Row],[Status]]=0,"",AC[[#This Row],[Status]]) -> Active
A11: Active | B11: AC-C | C11: AC Body | D11: Short 1" - Rene 41 | E11: Lehigh | F11: 250 | G11: 36259 | H11: 575 | I11: Rene 41 | J11: Precipitation Hardened | K11: None Observed | L11: 1 | M11: 25.4 | N11: 5 | O11: 127 | P11: 64.7 | Q11: 1910.7 | R11: ACME 2"-5 | S11: 265 | T11: 50000 | U11: 345 | W11: UCSB | X11: 39814 | Y11: - | Z11: - | AA11: https://drive.google.com/open?id=1ufwTYDKRXg9fWiytCJ2PaqUQyXha5s67&authuser=jrd419%40lehigh.edu&usp=drive_fs | CB11: HPS | CC11: =AC[[#This Row],[UID]] -> AC-C | CD11: Vessel | CF11: =AC[[#This Row],[Part Type]] -> AC Body | CG11: =AC[[#This Row],[Name]] -> Short 1" - Rene 41 | CH11: =RIGHT(AC[[#This Row],[UID]],LEN(AC[[#This Row],[UID]])-3) -> C | CL11: =IF(AC[[#This Row],[Status]]=0,"",AC[[#This Row],[Status]]) -> Active
A12: Active | B12: AC-D | C12: AC Body | D12: Short 1" - Rene 41 | E12: Lehigh | F12: 250 | G12: 36259 | H12: 575 | I12: Rene 41 | J12: Precipitation Hardened | K12: None Observed | L12: 1 | M12: 25.4 | N12: 5 | O12: 127 | P12: 64.7 | Q12: 1913.47 | R12: ACME 2"-5 | S12: 265 | T12: 50000 | U12: 345 | W12: UCSB | X12: 39814 | Y12: - | Z12: - | AA12: https://drive.google.com/open?id=1ufwTYDKRXg9fWiytCJ2PaqUQyXha5s67&authuser=jrd419%40lehigh.edu&usp=drive_fs | CB12: HPS | CC12: =AC[[#This Row],[UID]] -> AC-D | CD12: Vessel | CF12: =AC[[#This Row],[Part Type]] -> AC Body | CG12: =AC[[#This Row],[Name]] -> Short 1" - Rene 41 | CH12: =RIGHT(AC[[#This Row],[UID]],LEN(AC[[#This Row],[UID]])-3) -> D | CL12: =IF(AC[[#This Row],[Status]]=0,"",AC[[#This Row],[Status]]) -> Active
A13: Active | B13: AC-DUM-1 | C13: AC Body | D13: SS Dummy | E13: Lehigh | F13: - | G13: - | H13: - | I13: 316 SS | J13: - | K13: - | L13: - | M13: - | N13: - | O13: - | P13: - | Q13: - | R13: - | S13: - | T13: - | U13: - | W13: - | X13: - | Y13: - | Z13: - | AA13: - | CB13: HPS | CC13: =AC[[#This Row],[UID]] -> AC-DUM-1 | CD13: Vessel | CF13: =AC[[#This Row],[Part Type]] -> AC Body | CG13: =AC[[#This Row],[Name]] -> SS Dummy | CH13: =RIGHT(AC[[#This Row],[UID]],LEN(AC[[#This Row],[UID]])-3) -> DUM-1 | CL13: =IF(AC[[#This Row],[Status]]=0,"",AC[[#This Row],[Status]]) -> Active
A14: Active | B14: AC-E | C14: AC Body | D14: Short 1" - Inconel | E14: Lehigh | F14: 100 | G14: 14504 | H14: 575 | I14: Inconel 625 | J14: None | K14: None Observed | L14: 1 | M14: 25.4 | N14: 5 | O14: 127 | P14: 64.58 | Q14: 1856.92 | R14: ACME 2"-5 | S14: 115 | T14: 22500 | U14: 155 | W14: UCSB | X14: 39814 | Y14: - | Z14: - | AA14: https://drive.google.com/open?id=1ufwTYDKRXg9fWiytCJ2PaqUQyXha5s67&authuser=jrd419%40lehigh.edu&usp=drive_fs | CB14: HPS | CC14: =AC[[#This Row],[UID]] -> AC-E | CD14: Vessel | CF14: =AC[[#This Row],[Part Type]] -> AC Body | CG14: =AC[[#This Row],[Name]] -> Short 1" - Inconel | CH14: =RIGHT(AC[[#This Row],[UID]],LEN(AC[[#This Row],[UID]])-3) -> E | CL14: =IF(AC[[#This Row],[Status]]=0,"",AC[[#This Row],[Status]]) -> Active
A15: Active | B15: AC-F | C15: AC Body | D15: Short 1" - Inconel | E15: Lehigh | F15: 100 | G15: 14504 | H15: 575 | I15: Inconel 625 | J15: None | K15: None Observed | L15: 1 | M15: 25.4 | N15: 5 | O15: 127 | P15: 64.84 | Q15: 1856.76 | R15: ACME 2"-5 | S15: 115 | T15: 22500 | U15: 155 | W15: UCSB | X15: 39814 | Y15: - | Z15: - | AA15: https://drive.google.com/open?id=1ufwTYDKRXg9fWiytCJ2PaqUQyXha5s67&authuser=jrd419%40lehigh.edu&usp=drive_fs | CB15: HPS | CC15: =AC[[#This Row],[UID]] -> AC-F | CD15: Vessel | CF15: =AC[[#This Row],[Part Type]] -> AC Body | CG15: =AC[[#This Row],[Name]] -> Short 1" - Inconel | CH15: =RIGHT(AC[[#This Row],[UID]],LEN(AC[[#This Row],[UID]])-3) -> F | CL15: =IF(AC[[#This Row],[Status]]=0,"",AC[[#This Row],[Status]]) -> Active
A16: Active | B16: AC-G | C16: AC Body | D16: Short 1" - Inconel | E16: Lehigh | F16: 100 | G16: 14504 | H16: 575 | I16: Inconel 625 | J16: None | K16: None Observed | L16: 1 | M16: 25.4 | N16: 5 | O16: 127 | P16: 64.67 | Q16: 1880.05 | R16: ACME 2"-5 | S16: 115 | T16: 22500 | U16: 155 | W16: UCSB | X16: 39814 | Y16: - | Z16: - | AA16: https://drive.google.com/open?id=1ufwTYDKRXg9fWiytCJ2PaqUQyXha5s67&authuser=jrd419%40lehigh.edu&usp=drive_fs | CB16: HPS | CC16: =AC[[#This Row],[UID]] -> AC-G | CD16: Vessel | CF16: =AC[[#This Row],[Part Type]] -> AC Body | CG16: =AC[[#This Row],[Name]] -> Short 1" - Inconel | CH16: =RIGHT(AC[[#This Row],[UID]],LEN(AC[[#This Row],[UID]])-3) -> G | CL16: =IF(AC[[#This Row],[Status]]=0,"",AC[[#This Row],[Status]]) -> Active
A17: Active | B17: AC-H | C17: AC Body | D17: SS | E17: Lehigh | F17: 80 | G17: 11603 | H17: 420 | I17: SS 316 | J17: Unknown | K17: None Observed | L17: 1 | M17: 25.4 | N17: 10 | O17: 254 | P17: 125 | Q17: 6015.25 | R17: AMCE 2.5"-4 | S17: 95 | T17: 17500 | U17: 120 | W17: HIP | X17: 39814 | Y17: - | Z17: - | AA17: https://drive.google.com/open?id=1Cz8hYzXueZE-nMj2JosqjLtxxuqopeux&authuser=jrd419%40lehigh.edu&usp=drive_fs | CB17: HPS | CC17: =AC[[#This Row],[UID]] -> AC-H | CD17: Vessel | CF17: =AC[[#This Row],[Part Type]] -> AC Body | CG17: =AC[[#This Row],[Name]] -> SS | CH17: =RIGHT(AC[[#This Row],[UID]],LEN(AC[[#This Row],[UID]])-3) -> H | CL17: =IF(AC[[#This Row],[Status]]=0,"",AC[[#This Row],[Status]]) -> Active
A18: UCSB | B18: AC-K | C18: AC Body | D18: 400 MPa | E18: UCSB | F18: 400 | G18: 58015 | H18: 600 | I18: Rene 41 | J18: Precipitation Hardened | K18: None Observed | L18: - | M18: - | N18: - | O18: - | P18: 23.39 | Q18: - | R18: 1 1/8-12UNF-2B | S18: 420 | T18: 70000 | U18: 482 | W18: JSW | X18: 39845 | Y18: - | Z18: - | AA18: https://drive.google.com/open?id=1TVfObdRQCnDG1RncXQ3FIPc_Bi7SIp6O&authuser=jrd419%40lehigh.edu&usp=drive_fs | CB18: HPS | CC18: =AC[[#This Row],[UID]] -> AC-K | CD18: Vessel | CF18: =AC[[#This Row],[Part Type]] -> AC Body | CG18: =AC[[#This Row],[Name]] -> 400 MPa | CH18: =RIGHT(AC[[#This Row],[UID]],LEN(AC[[#This Row],[UID]])-3) -> K | CL18: =IF(AC[[#This Row],[Status]]=0,"",AC[[#This Row],[Status]]) -> UCSB
A19: UCSB | B19: AC-L | C19: AC Body | D19: 400 MPa | E19: UCSB | F19: 400 | G19: 58015 | H19: 600 | I19: Rene 41 | J19: Precipitation Hardened | K19: None Observed | L19: - | M19: - | N19: - | O19: - | P19: 23.39 | Q19: - | R19: 1 1/8-12UNF-2B | S19: 420 | T19: 70000 | U19: 482 | W19: JSW | X19: 40118 | Y19: - | Z19: - | AA19: https://drive.google.com/open?id=1TVfObdRQCnDG1RncXQ3FIPc_Bi7SIp6O&authuser=jrd419%40lehigh.edu&usp=drive_fs | CB19: HPS | CC19: =AC[[#This Row],[UID]] -> AC-L | CD19: Vessel | CF19: =AC[[#This Row],[Part Type]] -> AC Body | CG19: =AC[[#This Row],[Name]] -> 400 MPa | CH19: =RIGHT(AC[[#This Row],[UID]],LEN(AC[[#This Row],[UID]])-3) -> L | CL19: =IF(AC[[#This Row],[Status]]=0,"",AC[[#This Row],[Status]]) -> UCSB
A20: UCSB | B20: AC-M | C20: AC Body | D20: New 1" | E20: UCSB | F20: 200 | G20: 29008 | H20: 600 | I20: Rene 41 | J20: Precipitation Hardened | K20: None Observed | L20: 1 | M20: 25.4 | N20: 12 | O20: 304.8 | P20: 159.1 | Q20: - | R20: M60x4-6g | S20: 265 | T20: 45000 | U20: 310 | W20: JSW | X20: 39845 | Y20: - | Z20: - | AA20: https://drive.google.com/open?id=113d_Olu0z9ccyHV_PV5r8tnf4eArQJQH&authuser=jrd419%40lehigh.edu&usp=drive_fs | CB20: HPS | CC20: =AC[[#This Row],[UID]] -> AC-M | CD20: Vessel | CF20: =AC[[#This Row],[Part Type]] -> AC Body | CG20: =AC[[#This Row],[Name]] -> New 1" | CH20: =RIGHT(AC[[#This Row],[UID]],LEN(AC[[#This Row],[UID]])-3) -> M | CL20: =IF(AC[[#This Row],[Status]]=0,"",AC[[#This Row],[Status]]) -> UCSB
A21: UCSB | B21: AC-N | C21: AC Body | D21: New 1" | E21: UCSB | F21: 200 | G21: 29008 | H21: 600 | I21: Rene 41 | J21: Precipitation Hardened | K21: None Observed | L21: 1 | M21: 25.4 | N21: 12 | O21: 304.8 | P21: 161.8 | Q21: - | R21: M60x4-6g | S21: 265 | T21: 45000 | U21: 310 | W21: JSW | X21: 40118 | Y21: - | Z21: - | AA21: https://drive.google.com/open?id=113d_Olu0z9ccyHV_PV5r8tnf4eArQJQH&authuser=jrd419%40lehigh.edu&usp=drive_fs | CB21: HPS | CC21: =AC[[#This Row],[UID]] -> AC-N | CD21: Vessel | CF21: =AC[[#This Row],[Part Type]] -> AC Body | CG21: =AC[[#This Row],[Name]] -> New 1" | CH21: =RIGHT(AC[[#This Row],[UID]],LEN(AC[[#This Row],[UID]])-3) -> N | CL21: =IF(AC[[#This Row],[Status]]=0,"",AC[[#This Row],[Status]]) -> UCSB
A22: Active | B22: AC-P | C22: AC Body | D22: New 1" | E22: Lehigh | F22: 200 | G22: 29008 | H22: 600 | I22: Rene 41 | J22: Precipitation Hardened | K22: None Observed | L22: 1 | M22: 25.4 | N22: 12 | O22: 304.8 | P22: 159.1 | Q22: 5152.36 | R22: M60x4-6g | S22: 265 | T22: 50000 | U22: 345 | W22: JSW | X22: 40575 | Y22: - | Z22: - | AA22: https://drive.google.com/open?id=113d_Olu0z9ccyHV_PV5r8tnf4eArQJQH&authuser=jrd419%40lehigh.edu&usp=drive_fs | CB22: HPS | CC22: =AC[[#This Row],[UID]] -> AC-P | CD22: Vessel | CF22: =AC[[#This Row],[Part Type]] -> AC Body | CG22: =AC[[#This Row],[Name]] -> New 1" | CH22: =RIGHT(AC[[#This Row],[UID]],LEN(AC[[#This Row],[UID]])-3) -> P | CL22: =IF(AC[[#This Row],[Status]]=0,"",AC[[#This Row],[Status]]) -> Active
A23: Active | B23: AC-Parr | C23: AC Body | D23: Parr 4" | E23: Lehigh | K23: None Observed | L23: 3.75 | M23: 95.25 | N23: 10.44 | O23: 256.176 | P23: 1900 | R23: - | W23: UCSB | Y23: - | Z23: - | AA23: https://drive.google.com/open?id=1SiLNMuFYcr7wlVPzNkkXcVvHHqrw8UDd&authuser=jrd419%40lehigh.edu&usp=drive_fs | CB23: HPS | CC23: =AC[[#This Row],[UID]] -> AC-Parr | CD23: Vessel | CF23: =AC[[#This Row],[Part Type]] -> AC Body | CG23: =AC[[#This Row],[Name]] -> Parr 4" | CH23: =RIGHT(AC[[#This Row],[UID]],LEN(AC[[#This Row],[UID]])-3) -> Parr | CL23: =IF(AC[[#This Row],[Status]]=0,"",AC[[#This Row],[Status]]) -> Active
A24: Active | B24: AC-Q | C24: AC Body | D24: New 1" | E24: Lehigh | F24: 200 | G24: 29008 | H24: 600 | I24: Rene 41 | J24: Precipitation Hardened | K24: None Observed | L24: 1 | M24: 25.4 | N24: 12 | O24: 304.8 | P24: 157.87 | Q24: 5153.18 | R24: M60x4-6g | S24: 265 | T24: 50000 | U24: 345 | W24: JSW | X24: 40575 | Y24: - | Z24: - | AA24: https://drive.google.com/open?id=113d_Olu0z9ccyHV_PV5r8tnf4eArQJQH&authuser=jrd419%40lehigh.edu&usp=drive_fs | CB24: HPS | CC24: =AC[[#This Row],[UID]] -> AC-Q | CD24: Vessel | CF24: =AC[[#This Row],[Part Type]] -> AC Body | CG24: =AC[[#This Row],[Name]] -> New 1" | CH24: =RIGHT(AC[[#This Row],[UID]],LEN(AC[[#This Row],[UID]])-3) -> Q | CL24: =IF(AC[[#This Row],[Status]]=0,"",AC[[#This Row],[Status]]) -> Active
A25: Active | B25: AC-R | C25: AC Body | D25: New 1" | E25: Lehigh | F25: 200 | G25: 29008 | H25: 600 | I25: Rene 41 | J25: Precipitation Hardened | K25: None Observed | L25: 1 | M25: 25.4 | N25: 12 | O25: 304.8 | P25: 158.96 | Q25: 5140.09 | R25: M60x4-6g | S25: 265 | T25: 50000 | U25: 345 | W25: JSW | X25: 40575 | Y25: - | Z25: - | AA25: https://drive.google.com/open?id=113d_Olu0z9ccyHV_PV5r8tnf4eArQJQH&authuser=jrd419%40lehigh.edu&usp=drive_fs | CB25: HPS | CC25: =AC[[#This Row],[UID]] -> AC-R | CD25: Vessel | CF25: =AC[[#This Row],[Part Type]] -> AC Body | CG25: =AC[[#This Row],[Name]] -> New 1" | CH25: =RIGHT(AC[[#This Row],[UID]],LEN(AC[[#This Row],[UID]])-3) -> R | CL25: =IF(AC[[#This Row],[Status]]=0,"",AC[[#This Row],[Status]]) -> Active
A26: Active | B26: AC-TA | C26: AC Body | D26: TZM-13-260-10 | E26: Lehigh | F26: 16 | G26: 2320 | H26: 1000 | I26: TZM B387-19, Type 364 | J26: Stress-relieved | K26: None Observed | L26: 0.531 | M26: 13.5 | N26: 10.5 | O26: 266.7 | P26: 38.18 | Q26: 647.738 | R26: 7/8-14 RH&LH | S26: 16 | T26: 4500 | U26: 31 | W26: MTS | X26: 220914 | Y26: 481 / 31481 / 070122,WH:14 | Z26: PU055950 | AA26: https://drive.google.com/open?id=11HuA0hK7QDqJxJ2C8ydmKd7ep_n_RWv1&authuser=fsm217%40lehigh.edu&usp=drive_fs | CB26: HPS | CC26: =AC[[#This Row],[UID]] -> AC-TA | CD26: Vessel | CF26: =AC[[#This Row],[Part Type]] -> AC Body | CG26: =AC[[#This Row],[Name]] -> TZM-13-260-10 | CH26: =RIGHT(AC[[#This Row],[UID]],LEN(AC[[#This Row],[UID]])-3) -> TA | CL26: =IF(AC[[#This Row],[Status]]=0,"",AC[[#This Row],[Status]]) -> Active
A27: Active | B27: AC-TB | C27: AC Body | D27: TZM-13-260-10 | E27: Lehigh | F27: 16 | G27: 2320 | H27: 1000 | I27: TZM B387-19, Type 364 | J27: Stress-relieved | K27: None Observed | L27: 0.531 | M27: 13.5 | N27: 10.5 | O27: 266.7 | P27: 38.18 | Q27: 646.15267 | R27: 7/8-14 RH&LH | S27: 16 | T27: 4500 | U27: 31 | W27: MTS | X27: 220914 | Y27: 481 / 31481 / 070122,WH:14 | Z27: PU055950 | AA27: https://drive.google.com/open?id=11HuA0hK7QDqJxJ2C8ydmKd7ep_n_RWv1&authuser=fsm217%40lehigh.edu&usp=drive_fs | CB27: HPS | CC27: =AC[[#This Row],[UID]] -> AC-TB | CD27: Vessel | CF27: =AC[[#This Row],[Part Type]] -> AC Body | CG27: =AC[[#This Row],[Name]] -> TZM-13-260-10 | CH27: =RIGHT(AC[[#This Row],[UID]],LEN(AC[[#This Row],[UID]])-3) -> TB | CL27: =IF(AC[[#This Row],[Status]]=0,"",AC[[#This Row],[Status]]) -> Active
A28: Active | B28: AC-TC | C28: AC Body | D28: TZM-13-260-10 | E28: Lehigh | F28: 16 | G28: 2320 | H28: 1000 | I28: TZM B387-19, Type 364 | J28: Stress-relieved | K28: None Observed | L28: 0.531 | M28: 13.5 | N28: 10.5 | O28: 266.7 | P28: 38.18 | Q28: 641.007 | R28: 7/8-14 RH | S28: 16 | T28: 4500 | U28: 31 | W28: MTS | X28: 220428 | Y28: A78945 32570 | Z28: PU065371 | AA28: https://drive.google.com/open?id=1e4-heItkSoT4TKdDcrDT1Yz11ANbYO2u&authuser=fsm217%40lehigh.edu&usp=drive_fs | CB28: HPS | CC28: =AC[[#This Row],[UID]] -> AC-TC | CD28: Vessel | CF28: =AC[[#This Row],[Part Type]] -> AC Body | CG28: =AC[[#This Row],[Name]] -> TZM-13-260-10 | CH28: =RIGHT(AC[[#This Row],[UID]],LEN(AC[[#This Row],[UID]])-3) -> TC | CL28: =IF(AC[[#This Row],[Status]]=0,"",AC[[#This Row],[Status]]) -> Active
A29: Active | B29: AC-TD | C29: AC Body | D29: TZM-13-260-10 | E29: Lehigh | F29: 16 | G29: 2320 | H29: 1000 | I29: TZM B387-19, Type 364 | J29: Stress-relieved | K29: None Observed | L29: 0.531 | M29: 13.5 | N29: 10.5 | O29: 266.7 | P29: 38.18 | Q29: 639.074 | R29: 7/8-14 RH | S29: 16 | T29: 4500 | U29: 31 | W29: MTS | X29: 220428 | Y29: A78945 32570 | Z29: PU065371 | AA29: https://drive.google.com/open?id=1e4-heItkSoT4TKdDcrDT1Yz11ANbYO2u&authuser=fsm217%40lehigh.edu&usp=drive_fs | CB29: HPS | CC29: =AC[[#This Row],[UID]] -> AC-TD | CD29: Vessel | CF29: =AC[[#This Row],[Part Type]] -> AC Body | CG29: =AC[[#This Row],[Name]] -> TZM-13-260-10 | CH29: =RIGHT(AC[[#This Row],[UID]],LEN(AC[[#This Row],[UID]])-3) -> TD | CL29: =IF(AC[[#This Row],[Status]]=0,"",AC[[#This Row],[Status]]) -> Active
A30: Active | B30: AC-TE | C30: AC Body | D30: TZM-13-260-10 | E30: Lehigh | F30: 16 | G30: 2320 | H30: 1000 | I30: TZM B387-19, Type 364 | J30: Stress-relieved | K30: None Observed | L30: 0.531 | M30: 13.5 | N30: 10.5 | O30: 266.7 | P30: 38.18 | Q30: 637.872 | R30: 7/8-14 RH | S30: 16 | T30: 4500 | U30: 31 | W30: MTS | X30: 220428 | Y30: A78945 32570 | Z30: PU065371 | AA30: https://drive.google.com/open?id=1e4-heItkSoT4TKdDcrDT1Yz11ANbYO2u&authuser=fsm217%40lehigh.edu&usp=drive_fs | CB30: HPS | CC30: =AC[[#This Row],[UID]] -> AC-TE | CD30: Vessel | CF30: =AC[[#This Row],[Part Type]] -> AC Body | CG30: =AC[[#This Row],[Name]] -> TZM-13-260-10 | CH30: =RIGHT(AC[[#This Row],[UID]],LEN(AC[[#This Row],[UID]])-3) -> TE | CL30: =IF(AC[[#This Row],[Status]]=0,"",AC[[#This Row],[Status]]) -> Active
A31: New | B31: AC-TF | C31: AC Body | D31: TZM-13-260-13 | E31: Lehigh | F31: 16 | G31: 2320 | H31: 1000 | I31: TZM B387 Type 364 | J31: Stress-relieved | K31: None Observed | L31: 0.531 | M31: 13.5 | N31: 13.5 | O31: 342.9 | P31: 38.18 | Q31: 672.743 | R31: 7/8-14 RH&RH | S31: 16 | T31: 4500 | U31: 31 | V31: "{ "Axial Position (mm)": [0,0.79,0.8,342.11,342.31,342.61,342.9], "Cross-Sectional Area (mm^2)": [375.73,308.3,143.14,308.3,310.36,324.72,375.73], "Contact Plane": ["SP-FACE-M-v","","","","","","SP-FACE-M-^"], "Transition Model": ["2863.4*x**6 - 8057.9*x**5 + 9073.6*x**4 - 5266.3*x**3 + 1770.5*x**2 - 413.44*x + 375.72","Constant","Constant","64.00000000*x**2 - 43792.57999996*x + 7491675.70939319","58.33333333*x**3 - 59842.24999872*x**2 + 20463401.3937302*x - 2332525840.61997","2438.39483767*x**3 - 2506766.8844556*x**2 + 859018772.787831*x - 98122848429.1125","Constant"] }" | W31: Efinea | X31: 240709 | Y31: #523240625 / TZM240523 | Z31: PU087594 | CB31: HPS | CC31: =AC[[#This Row],[UID]] -> AC-TF | CD31: Vessel | CF31: =AC[[#This Row],[Part Type]] -> AC Body | CG31: =AC[[#This Row],[Name]] -> TZM-13-260-13 | CH31: =RIGHT(AC[[#This Row],[UID]],LEN(AC[[#This Row],[UID]])-3) -> TF | CL31: =IF(AC[[#This Row],[Status]]=0,"",AC[[#This Row],[Status]]) -> New
A32: New | B32: AC-TG | C32: AC Body | D32: TZM-13-260-10-DE | E32: Lehigh | F32: 16 | G32: 2320 | H32: 1000 | I32: TZM B387 Type 364 | J32: Stress-relieved | K32: None Observed | L32: 0.531 | M32: 13.5 | N32: 10.5 | O32: 266.7 | P32: 38.18 | Q32: 833.428 | R32: 7/8-14 RH&DeadEnd | S32: 16 | T32: 4500 | U32: 31 | V32: "{ "Axial Position (mm)": [0,9.53,16.28,265.91,265.92,266.3,266.7], "Cross-Sectional Area (mm^2)": [0,1,143.14,143.14,168.11,172.73,202.39], "Contact Plane": ["MP-REST-S-v","","","","","","SP-FACE-M-^"], "Transition Model": ["Constant","-0.0013513259*x**5 + 0.0923648179*x**4 - 2.5143650631*x**3 + 30.9322769461*x**2 - 127.5836205896*x - 71.8248929645","Constant","Constant","9.4507101625*x**4 - 10046.2260390019*x**3 + 4004750.72914589*x**2 - 709525967.113341*x + 47140605165.743","2383.3333333433*x**4 - 2539998.33334398*x**3 + 1015110580.67095*x**2 - 180306245316.931*x + 12009901986121.7","Constant"] }" | W32: Efinea | X32: 240709 | Y32: #523240625 / TZM240523 | Z32: PU087594 | CB32: HPS | CC32: =AC[[#This Row],[UID]] -> AC-TG | CD32: Vessel | CF32: =AC[[#This Row],[Part Type]] -> AC Body | CG32: =AC[[#This Row],[Name]] -> TZM-13-260-10-DE | CH32: =RIGHT(AC[[#This Row],[UID]],LEN(AC[[#This Row],[UID]])-3) -> TG | CL32: =IF(AC[[#This Row],[Status]]=0,"",AC[[#This Row],[Status]]) -> New
A33: UCSB | B33: AC-Z | C33: AC Body | D33: 2" | E33: UCSB | F33: 270 | G33: 43511 | H33: 600 | I33: Rene 41 | J33: Precipitation Hardened | K33: None Observed | L33: - | M33: - | N33: - | O33: - | P33: - | Q33: - | R33: - | S33: 315 | T33: 60000 | U33: 415 | W33: JSW | X33: 40118 | Y33: - | Z33: - | AA33: https://drive.google.com/open?id=11_I3GHd-ONX5mnhum8FPQixS8TAu2a1d&authuser=jrd419%40lehigh.edu&usp=drive_fs | CB33: HPS | CC33: =AC[[#This Row],[UID]] -> AC-Z | CD33: Vessel | CF33: =AC[[#This Row],[Part Type]] -> AC Body | CG33: =AC[[#This Row],[Name]] -> 2" | CH33: =RIGHT(AC[[#This Row],[UID]],LEN(AC[[#This Row],[UID]])-3) -> Z | CL33: =IF(AC[[#This Row],[Status]]=0,"",AC[[#This Row],[Status]]) -> UCSB
CB34: HPS | CC34: =AC[[#This Row],[UID]] -> 0 | CD34: Vessel | CF34: =AC[[#This Row],[Part Type]] -> 0 | CG34: =AC[[#This Row],[Name]] -> 0 | CH34: =RIGHT(AC[[#This Row],[UID]],LEN(AC[[#This Row],[UID]])-3) -> #VALUE! | CL34: =IF(AC[[#This Row],[Status]]=0,"",AC[[#This Row],[Status]])
CB35: HPS | CC35: =AC[[#This Row],[UID]] -> 0 | CD35: Vessel | CF35: =AC[[#This Row],[Part Type]] -> 0 | CG35: =AC[[#This Row],[Name]] -> 0 | CH35: =RIGHT(AC[[#This Row],[UID]],LEN(AC[[#This Row],[UID]])-3) -> #VALUE! | CL35: =IF(AC[[#This Row],[Status]]=0,"",AC[[#This Row],[Status]])
CB36: HPS | CC36: =AC[[#This Row],[UID]] -> 0 | CD36: Vessel | CF36: =AC[[#This Row],[Part Type]] -> 0 | CG36: =AC[[#This Row],[Name]] -> 0 | CH36: =RIGHT(AC[[#This Row],[UID]],LEN(AC[[#This Row],[UID]])-3) -> #VALUE! | CL36: =IF(AC[[#This Row],[Status]]=0,"",AC[[#This Row],[Status]])
CB37: HPS | CC37: =AC[[#This Row],[UID]] -> 0 | CD37: Vessel | CF37: =AC[[#This Row],[Part Type]] -> 0 | CG37: =AC[[#This Row],[Name]] -> 0 | CH37: =RIGHT(AC[[#This Row],[UID]],LEN(AC[[#This Row],[UID]])-3) -> #VALUE! | CL37: =IF(AC[[#This Row],[Status]]=0,"",AC[[#This Row],[Status]])
CB38: HPS | CC38: =AC[[#This Row],[UID]] -> 0 | CD38: Vessel | CF38: =AC[[#This Row],[Part Type]] -> 0 | CG38: =AC[[#This Row],[Name]] -> 0 | CH38: =RIGHT(AC[[#This Row],[UID]],LEN(AC[[#This Row],[UID]])-3) -> #VALUE! | CL38: =IF(AC[[#This Row],[Status]]=0,"",AC[[#This Row],[Status]])
CB39: HPS | CC39: =AC[[#This Row],[UID]] -> 0 | CD39: Vessel | CF39: =AC[[#This Row],[Part Type]] -> 0 | CG39: =AC[[#This Row],[Name]] -> 0 | CH39: =RIGHT(AC[[#This Row],[UID]],LEN(AC[[#This Row],[UID]])-3) -> #VALUE! | CL39: =IF(AC[[#This Row],[Status]]=0,"",AC[[#This Row],[Status]])
CB40: HPS | CC40: =AC[[#This Row],[UID]] -> 0 | CD40: Vessel | CF40: =AC[[#This Row],[Part Type]] -> 0 | CG40: =AC[[#This Row],[Name]] -> 0 | CH40: =RIGHT(AC[[#This Row],[UID]],LEN(AC[[#This Row],[UID]])-3) -> #VALUE! | CL40: =IF(AC[[#This Row],[Status]]=0,"",AC[[#This Row],[Status]])
...

Sheet AD
A1: Status | B1: Part Type | C1: UID | D1: Pressure Rating (psi) | E1: Part Nr. | F1: Mass Measurment Date | G1: Mass (g) | H1: Inlet 1 | I1: Inlet 2 | J1: Length (inch) | K1: ID (inch) | L1: Type | M1: Material | N1: Prior UnitID | O1: Notes | P1: PO | Q1: Vendor | R1: Website | BZ1: EXP Style | CA1: Setup Location | CB1: Setup Sub-Location | CC1: Sub-Setup Assembly | CD1: IO type | CE1: Zone | CF1: Device Type | CG1: Device Tag | CH1: Device Location | CI1: Circuit | CJ1: Power Source | CK1: Status
A2: Superceded | B2: Adaptors | C2: AD-K2 | D2: 60000 | E2: 60-21HF4HF6 | F2: 220930 | G2: 162.69 | H2: F375C | I2: F250C | J2: 1.625 | K2: 0.0625 | L2: Long | M2: 316 SS | N2: - | O2: - | P2: UCSB | Q2: HIP | R2: https://www.highpressure.com/pdfs/section/Accessories.pdf | BZ2: Table Format | CA2: HPS | CB2: AC | CC2: Vessel | CE2: =AD[[#This Row],[Part Type]] -> Adaptors | CF2: =AD[[#This Row],[Part Nr.]] -> 60-21HF4HF6 | CG2: =AD[[#This Row],[UID]] -> AD-K2 | CK2: =IF(AD[[#This Row],[Status]]=0,"",AD[[#This Row],[Status]]) -> Superceded
A3: Superceded | B3: Adaptors | C3: AD-L1 | D3: 60000 | E3: 60-21HF4HF6 | F3: 220930 | G3: 162.701 | H3: F375C | I3: F250C | J3: 1.625 | K3: 0.0625 | L3: Long | M3: 316 SS | N3: - | O3: - | P3: UCSB | Q3: HIP | R3: https://www.highpressure.com/pdfs/section/Accessories.pdf | CA3: HPS | CB3: AC | CC3: Vessel | CE3: =AD[[#This Row],[Part Type]] -> Adaptors | CF3: =AD[[#This Row],[Part Nr.]] -> 60-21HF4HF6 | CG3: =AD[[#This Row],[UID]] -> AD-L1 | CK3: =IF(AD[[#This Row],[Status]]=0,"",AD[[#This Row],[Status]]) -> Superceded
A4: Superceded | B4: Adaptors | C4: AD-N1 | D4: 60000 | E4: 60-21HF4HF6 | F4: 220930 | G4: 162.811 | H4: F375C | I4: F250C | J4: 1.625 | K4: 0.0625 | L4: Long | M4: 316 SS | N4: - | O4: - | P4: UCSB | Q4: HIP | R4: https://www.highpressure.com/pdfs/section/Accessories.pdf | CA4: HPS | CB4: AC | CC4: Vessel | CE4: =AD[[#This Row],[Part Type]] -> Adaptors | CF4: =AD[[#This Row],[Part Nr.]] -> 60-21HF4HF6 | CG4: =AD[[#This Row],[UID]] -> AD-N1 | CK4: =IF(AD[[#This Row],[Status]]=0,"",AD[[#This Row],[Status]]) -> Superceded
A5: Superceded | B5: Adaptors | C5: AD-P1 | D5: 60000 | E5: 60-21HF4HF6 | F5: 220930 | G5: 160.929 | H5: F375C | I5: F250C | J5: 1.625 | K5: 0.0625 | L5: Long | M5: 316 SS | N5: - | O5: - | P5: UCSB | Q5: HIP | R5: https://www.highpressure.com/pdfs/section/Accessories.pdf | CA5: HPS | CB5: AC | CC5: Vessel | CE5: =AD[[#This Row],[Part Type]] -> Adaptors | CF5: =AD[[#This Row],[Part Nr.]] -> 60-21HF4HF6 | CG5: =AD[[#This Row],[UID]] -> AD-P1 | CK5: =IF(AD[[#This Row],[Status]]=0,"",AD[[#This Row],[Status]]) -> Superceded
A6: Superceded | B6: Adaptors | C6: AD-Q1 | D6: 60000 | E6: 60-21HF4HF6 | F6: 220930 | G6: 161.149 | H6: F375C | I6: F250C | J6: 1.625 | K6: 0.0625 | L6: Long | M6: 316 SS | N6: - | O6: - | P6: UCSB | Q6: HIP | R6: https://www.highpressure.com/pdfs/section/Accessories.pdf | CA6: HPS | CB6: AC | CC6: Vessel | CE6: =AD[[#This Row],[Part Type]] -> Adaptors | CF6: =AD[[#This Row],[Part Nr.]] -> 60-21HF4HF6 | CG6: =AD[[#This Row],[UID]] -> AD-Q1 | CK6: =IF(AD[[#This Row],[Status]]=0,"",AD[[#This Row],[Status]]) -> Superceded
A7: Superceded | B7: Adaptors | C7: AD-R1 | D7: 60000 | E7: 60-21HF4HF6 | F7: 220930 | G7: 160.993 | H7: F375C | I7: F250C | J7: 1.625 | K7: 0.0625 | L7: Long | M7: 316 SS | N7: - | O7: - | P7: UCSB | Q7: HIP | R7: https://www.highpressure.com/pdfs/section/Accessories.pdf | CA7: HPS | CB7: AC | CC7: Vessel | CE7: =AD[[#This Row],[Part Type]] -> Adaptors | CF7: =AD[[#This Row],[Part Nr.]] -> 60-21HF4HF6 | CG7: =AD[[#This Row],[UID]] -> AD-R1 | CK7: =IF(AD[[#This Row],[Status]]=0,"",AD[[#This Row],[Status]]) -> Superceded
A8: Active | B8: Adaptors | C8: AD-1 | D8: 60000 | E8: 60-21HF6HM4 | F8: 220929 | G8: 418.217 | H8: F375C | I8: M250C | J8: 1.75 | K8: 0.0625 | L8: Short | M8: 316 SS | N8: - | O8: - | P8: UCSB | Q8: HIP | R8: https://www.highpressure.com/pdfs/section/Accessories.pdf | CA8: HPS | CB8: AC | CC8: Vessel | CE8: =AD[[#This Row],[Part Type]] -> Adaptors | CF8: =AD[[#This Row],[Part Nr.]] -> 60-21HF6HM4 | CG8: =AD[[#This Row],[UID]] -> AD-1 | CK8: =IF(AD[[#This Row],[Status]]=0,"",AD[[#This Row],[Status]]) -> Active
A9: Active | B9: Adaptors | C9: AD-2 | D9: 60000 | E9: 60-21HF6HM4 | F9: 220930 | G9: 416.151 | H9: F375C | I9: M250C | J9: 1.75 | K9: 0.0625 | L9: Short | M9: 316 SS | N9: - | O9: - | P9: UCSB | Q9: HIP | R9: https://www.highpressure.com/pdfs/section/Accessories.pdf | CA9: HPS | CB9: AC | CC9: Vessel | CE9: =AD[[#This Row],[Part Type]] -> Adaptors | CF9: =AD[[#This Row],[Part Nr.]] -> 60-21HF6HM4 | CG9: =AD[[#This Row],[UID]] -> AD-2 | CK9: =IF(AD[[#This Row],[Status]]=0,"",AD[[#This Row],[Status]]) -> Active
A10: Active | B10: Adaptors | C10: AD-3 | D10: 60000 | E10: 60-21HF6HM4 | F10: 220930 | G10: 417.313 | H10: F375C | I10: M250C | J10: 1.75 | K10: 0.0625 | L10: Short | M10: 316 SS | N10: - | O10: - | P10: UCSB | Q10: HIP | R10: https://www.highpressure.com/pdfs/section/Accessories.pdf | CA10: HPS | CB10: AC | CC10: Vessel | CE10: =AD[[#This Row],[Part Type]] -> Adaptors | CF10: =AD[[#This Row],[Part Nr.]] -> 60-21HF6HM4 | CG10: =AD[[#This Row],[UID]] -> AD-3 | CK10: =IF(AD[[#This Row],[Status]]=0,"",AD[[#This Row],[Status]]) -> Active
A11: Active | B11: Adaptors | C11: AD-4 | D11: 60000 | E11: 60-21HF6HM4 | F11: 220930 | G11: 417.173 | H11: F375C | I11: M250C | J11: 1.75 | K11: 0.0625 | L11: Short | M11: 316 SS | N11: - | O11: - | P11: UCSB | Q11: HIP | R11: https://www.highpressure.com/pdfs/section/Accessories.pdf | CA11: HPS | CB11: AC | CC11: Vessel | CE11: =AD[[#This Row],[Part Type]] -> Adaptors | CF11: =AD[[#This Row],[Part Nr.]] -> 60-21HF6HM4 | CG11: =AD[[#This Row],[UID]] -> AD-4 | CK11: =IF(AD[[#This Row],[Status]]=0,"",AD[[#This Row],[Status]]) -> Active
A12: Active | B12: Adaptors | C12: AD-5 | D12: 60000 | E12: 60-21HF6HM4 | F12: 220930 | G12: 415.3 | H12: F375C | I12: M250C | J12: 1.75 | K12: 0.0625 | L12: Short | M12: 316 SS | N12: - | O12: - | P12: UCSB | Q12: HIP | R12: https://www.highpressure.com/pdfs/section/Accessories.pdf | CA12: HPS | CB12: AC | CC12: Vessel | CE12: =AD[[#This Row],[Part Type]] -> Adaptors | CF12: =AD[[#This Row],[Part Nr.]] -> 60-21HF6HM4 | CG12: =AD[[#This Row],[UID]] -> AD-5 | CK12: =IF(AD[[#This Row],[Status]]=0,"",AD[[#This Row],[Status]]) -> Active
A13: Active | B13: Adaptors | C13: AD-6 | D13: 60000 | E13: 60-21HF6HM4 | F13: 220930 | G13: 408.122 | H13: F375C | I13: M250C | J13: 1.75 | K13: 0.0625 | L13: Short | M13: 316 SS | N13: - | O13: - | P13: UCSB | Q13: HIP | R13: https://www.highpressure.com/pdfs/section/Accessories.pdf | CA13: HPS | CB13: AC | CC13: Vessel | CE13: =AD[[#This Row],[Part Type]] -> Adaptors | CF13: =AD[[#This Row],[Part Nr.]] -> 60-21HF6HM4 | CG13: =AD[[#This Row],[UID]] -> AD-6 | CK13: =IF(AD[[#This Row],[Status]]=0,"",AD[[#This Row],[Status]]) -> Active
A14: Retired | B14: Adaptors | C14: AD-7 | D14: 60000 | E14: 60-21HF6HM4 | F14: 220930 | G14: 416.68 | H14: F375C | I14: M250C | J14: 1.75 | K14: 0.0625 | L14: Short | M14: 316 SS | N14: - | O14: - | P14: UCSB | Q14: HIP | R14: https://www.highpressure.com/pdfs/section/Accessories.pdf | CA14: HPS | CB14: AC | CC14: Vessel | CE14: =AD[[#This Row],[Part Type]] -> Adaptors | CF14: =AD[[#This Row],[Part Nr.]] -> 60-21HF6HM4 | CG14: =AD[[#This Row],[UID]] -> AD-7 | CK14: =IF(AD[[#This Row],[Status]]=0,"",AD[[#This Row],[Status]]) -> Retired
... A47: Active | B47: Adaptors | C47: AD-40 | D47: 100000 | E47: 100-21XF6XM4 | F47: 230215 | G47: 202.686 | H47: F375C | I47: M250C | J47: 2.5 | K47: 0.0625 | L47: Short | M47: Inconel 718 | N47: - | O47: - | P47: UCSB | Q47: HIP | R47: https://www.highpressure.com/pdfs/section/Accessories.pdf | CA47: HPS | CB47: AC | CC47: Vessel | CE47: =AD[[#This Row],[Part Type]] -> Adaptors | CF47: =AD[[#This Row],[Part Nr.]] -> 100-21XF6XM4 | CG47: =AD[[#This Row],[UID]] -> AD-40 | CK47: =IF(AD[[#This Row],[Status]]=0,"",AD[[#This Row],[Status]]) -> Active
A48: Active | B48: Adaptors | C48: AD-41 | D48: 60000 | E48: Custom | F48: 250131 | G48: 742.767 | CA48: HPS | CB48: AC | CC48: Vessel | CE48: =AD[[#This Row],[Part Type]] -> Adaptors | CF48: =AD[[#This Row],[Part Nr.]] -> Custom | CG48: =AD[[#This Row],[UID]] -> AD-41 | CK48: =IF(AD[[#This Row],[Status]]=0,"",AD[[#This Row],[Status]]) -> Active
A49: Active | B49: Adaptors | C49: AD-42 | D49: 60000 | E49: Custom | F49: 250131 | G49: 739.566 | CA49: HPS | CB49: AC | CC49: Vessel | CE49: =AD[[#This Row],[Part Type]] -> Adaptors | CF49: =AD[[#This Row],[Part Nr.]] -> Custom | CG49: =AD[[#This Row],[UID]] -> AD-42 | CK49: =IF(AD[[#This Row],[Status]]=0,"",AD[[#This Row],[Status]]) -> Active
CA50: HPS | CB50: AC | CC50: Vessel | CE50: =AD[[#This Row],[Part Type]] -> 0 | CF50: =AD[[#This Row],[Part Nr.]] -> 0 | CG50: =AD[[#This Row],[UID]] -> 0 | CK50: =IF(AD[[#This Row],[Status]]=0,"",AD[[#This Row],[Status]])
CA51: HPS | CB51: AC | CC51: Vessel | CE51: =AD[[#This Row],[Part Type]] -> 0 | CF51: =AD[[#This Row],[Part Nr.]] -> 0 | CG51: =AD[[#This Row],[UID]] -> 0 | CK51: =IF(AD[[#This Row],[Status]]=0,"",AD[[#This Row],[Status]])
CA52: HPS | CB52: AC | CC52: Vessel | CE52: =AD[[#This Row],[Part Type]] -> 0 | CF52: =AD[[#This Row],[Part Nr.]] -> 0 | CG52: =AD[[#This Row],[UID]] -> 0 | CK52: =IF(AD[[#This Row],[Status]]=0,"",AD[[#This Row],[Status]])
CA53: HPS | CB53: AC | CC53: Vessel | CE53: =AD[[#This Row],[Part Type]] -> 0 | CF53: =AD[[#This Row],[Part Nr.]] -> 0 | CG53: =AD[[#This Row],[UID]] -> 0 | CK53: =IF(AD[[#This Row],[Status]]=0,"",AD[[#This Row],[Status]])
CA54: HPS | CB54: AC | CC54: Vessel | CE54: =AD[[#This Row],[Part Type]] -> 0 | CF54: =AD[[#This Row],[Part Nr.]] -> 0 | CG54: =AD[[#This Row],[UID]] -> 0 | CK54: =IF(AD[[#This Row],[Status]]=0,"",AD[[#This Row],[Status]])
CA55: HPS | CB55: AC | CC55: Vessel | CE55: =AD[[#This Row],[Part Type]] -> 0 | CF55: =AD[[#This Row],[Part Nr.]] -> 0 | CG55: =AD[[#This Row],[UID]] -> 0 | CK55: =IF(AD[[#This Row],[Status]]=0,"",AD[[#This Row],[Status]])
CA56: HPS | CB56: AC | CC56: Vessel | CE56: =AD[[#This Row],[Part Type]] -> 0 | CF56: =AD[[#This Row],[Part Nr.]] -> 0 | CG56: =AD[[#This Row],[UID]] -> 0 | CK56: =IF(AD[[#This Row],[Status]]=0,"",AD[[#This Row],[Status]])
CA57: HPS | CB57: AC | CC57: Vessel | CE57: =AD[[#This Row],[Part Type]] -> 0 | CF57: =AD[[#This Row],[Part Nr.]] -> 0 | CG57: =AD[[#This Row],[UID]] -> 0 | CK57: =IF(AD[[#This Row],[Status]]=0,"",AD[[#This Row],[Status]])
CA58: HPS | CB58: AC | CC58: Vessel | CE58: =AD[[#This Row],[Part Type]] -> 0 | CF58: =AD[[#This Row],[Part Nr.]] -> 0 | CG58: =AD[[#This Row],[UID]] -> 0 | CK58: =IF(AD[[#This Row],[Status]]=0,"",AD[[#This Row],[Status]])
CA59: HPS | CB59: AC | CC59: Vessel | CE59: =AD[[#This Row],[Part Type]] -> 0 | CF59: =AD[[#This Row],[Part Nr.]] -> 0 | CG59: =AD[[#This Row],[UID]] -> 0 | CK59: =IF(AD[[#This Row],[Status]]=0,"",AD[[#This Row],[Status]])
CA60: HPS | CB60: AC | CC60: Vessel | CE60: =AD[[#This Row],[Part Type]] -> 0 | CF60: =AD[[#This Row],[Part Nr.]] -> 0 | CG60: =AD[[#This Row],[UID]] -> 0 | CK60: =IF(AD[[#This Row],[Status]]=0,"",AD[[#This Row],[Status]])
CA61: HPS | CB61: AC | CC61: Vessel | CE61: =AD[[#This Row],[Part Type]] -> 0 | CF61: =AD[[#This Row],[Part Nr.]] -> 0 | CG61: =AD[[#This Row],[UID]] -> 0 | CK61: =IF(AD[[#This Row],[Status]]=0,"",AD[[#This Row],[Status]])
... CA111: HPS | CB111: AC | CC111: Vessel | CE111: =AD[[#This Row],[Part Type]] -> 0 | CF111: =AD[[#This Row],[Part Nr.]] -> 0 | CG111: =AD[[#This Row],[UID]] -> 0 | CK111: =IF(AD[[#This Row],[Status]]=0,"",AD[[#This Row],[Status]])

Sheet CR
A1: Status | B1: Part Type | C1: UID | D1: Pressure Rating (psi) | E1: Part Nr. | F1: Mass Measurment Date | G1: Mass (g) | H1: Inlet 1 | I1: Inlet 2 | J1: Inlet 3 | K1: Inlet 4 | L1: Length (inch) | M1: Width (inch) | N1: Depth (inch) | O1: ID (inch) | P1: Type | Q1: Material | R1: Prior UnitID | S1: Notes | T1: PO | U1: Vendor | V1: Website | BZ1: EXP Style | CA1: Setup Location | CB1: Setup Sub-Location | CC1: Sub-Setup Assembly | CD1: IO type | CE1: Zone | CF1: Device Type | CG1: Device Tag | CH1: Device Location | CI1: Circuit | CJ1: Power Source | CK1: Status
